<?xml version="1.0" ?>
<!-- =================================================================================== -->
<!-- |    This document was autogenerated by xacro from proto3.urdf.xacro              | -->
<!-- |    EDITING THIS FILE BY HAND IS NOT RECOMMENDED                                 | -->
<!-- =================================================================================== -->
<robot name="astro2" xmlns:xacro="http://ros.org/wiki/xacro">
  <!-- Colours -->
  <material name="blue">
    <color rgba="0 0 0.7 1"/>
  </material>
  <material name="black">
    <color rgba="0 0 0 1"/>
  </material>
  <material name="silver">
    <color rgba="0.9 0.9 0.9 1"/>
  </material>
  <material name="iron">
    <color rgba="0.6 0.6 0.6 1"/>
  </material>
  <material name="brown">
    <color rgba="0.87 0.72 0.53 1"/>
  </material>
  <link name="base_link">
    <visual>
      <geometry>
        <box size="0.76 0.47 0.78"/>
      </geometry>
      <material name="blue"/>
    </visual>
    <collision>
      <geometry>
        <box size="0.76 0.47 0.78"/>
      </geometry>
    </collision>
    <inertial>
      <mass value="40"/>
      <inertia ixx="3.95333333318" ixy="0.0" ixz="0.0" iyy="2.66166666656" iyz="0.0" izz="2.76433333322"/>
    </inertial>
  </link>
  <link name="camera_support_link">
    <visual>
      <geometry>
        <cylinder length="0.13" radius="0.016"/>
      </geometry>
      <origin rpy="0 0 0" xyz="0 0 0.065"/>
      <material name="silver"/>
    </visual>
    <collision>
      <geometry>
        <cylinder length="0.13" radius="0.016"/>
      </geometry>
      <origin rpy="0 0 0" xyz="0 0 0.065"/>
    </collision>
    <inertial>
      <mass value="0.2"/>
      <inertia ixx="0.003" ixy="0.0" ixz="0.0" iyy="0.003" iyz="0.0" izz="0.003"/>
    </inertial>
  </link>
  <joint name="camera_support_joint" type="fixed">
    <parent link="base_link"/>
    <child link="camera_support_link"/>
    <origin xyz="0 0 0.39"/>
  </joint>
  <link name="camera_servo_link">
    <visual>
      <geometry>
        <box size="0.02 0.04 0.0258"/>
      </geometry>
      <origin rpy="0 0 0" xyz="0 0 0.0129"/>
      <material name="blue"/>
    </visual>
    <collision>
      <geometry>
        <box size="0.02 0.04 0.0258"/>
      </geometry>
      <origin rpy="0 0 0" xyz="0 0 0.0129"/>
    </collision>
    <inertial>
      <mass value="0.05"/>
      <inertia ixx="0.0005" ixy="0.0" ixz="0.0" iyy="0.0005" iyz="0.0" izz="0.0005"/>
    </inertial>
  </link>
  <joint name="camera_servo_joint" type="revolute">
    <axis xyz="0 0 1"/>
    <limit effort="1000.0" lower="-1.57" upper="1.57" velocity="0.5"/>
    <parent link="camera_support_link"/>
    <child link="camera_servo_link"/>
    <origin xyz="0 0 0.13"/>
  </joint>
  <material name="aluminum">
    <color rgba="0.5 0.5 0.5 1"/>
  </material>
  <!-- camera body, with origin at bottom screw mount -->
  <joint name="camera_joint" type="fixed">
    <origin rpy="0 0 0" xyz="0 0 0.0258"/>
    <parent link="camera_servo_link"/>
    <child link="camera_bottom_screw_frame"/>
  </joint>
  <link name="camera_bottom_screw_frame"/>
  <joint name="camera_link_joint" type="fixed">
    <origin rpy="0 0 0" xyz="0 0.02 0.0115"/>
    <parent link="camera_bottom_screw_frame"/>
    <child link="camera_link"/>
  </joint>
  <link name="camera_link">
    <visual>
      <origin rpy="1.57079632679 0 1.57079632679" xyz="0.00987 -0.02 0"/>
      <geometry>
        <!-- <box size="${d415_cam_width} ${d415_cam_height} ${d415_cam_depth}"/> -->
        <mesh filename="package://realsense2_camera/meshes/d415.stl"/>
      </geometry>
      <material name="aluminum"/>
    </visual>
    <collision>
      <origin rpy="0 0 0" xyz="0 -0.02 0"/>
      <geometry>
        <box size="0.02005 0.099 0.023"/>
      </geometry>
    </collision>
    <inertial>
      <!-- The following are not reliable values, and should not be used for modeling -->
      <mass value="0.564"/>
      <origin xyz="0 0 0"/>
      <inertia ixx="0.003881243" ixy="0.0" ixz="0.0" iyy="0.000498940" iyz="0.0" izz="0.003879257"/>
    </inertial>
  </link>
  <!-- camera depth joints and links -->
  <joint name="camera_depth_joint" type="fixed">
    <origin rpy="0 0 0" xyz="0 0 0"/>
    <parent link="camera_link"/>
    <child link="camera_depth_frame"/>
  </joint>
  <link name="camera_depth_frame"/>
  <joint name="camera_depth_optical_joint" type="fixed">
    <origin rpy="-1.57079632679 0 -1.57079632679" xyz="0 0 0"/>
    <parent link="camera_depth_frame"/>
    <child link="camera_depth_optical_frame"/>
  </joint>
  <link name="camera_depth_optical_frame"/>
  <!-- camera left IR joints and links -->
  <joint name="camera_left_ir_joint" type="fixed">
    <origin rpy="0 0 0" xyz="0 0.0 0"/>
    <parent link="camera_depth_frame"/>
    <child link="camera_left_ir_frame"/>
  </joint>
  <link name="camera_left_ir_frame"/>
  <joint name="camera_left_ir_optical_joint" type="fixed">
    <origin rpy="-1.57079632679 0 -1.57079632679" xyz="0 0 0"/>
    <parent link="camera_left_ir_frame"/>
    <child link="camera_left_ir_optical_frame"/>
  </joint>
  <link name="camera_left_ir_optical_frame"/>
  <!-- camera right IR joints and links -->
  <joint name="camera_right_ir_joint" type="fixed">
    <origin rpy="0 0 0" xyz="0 -0.055 0"/>
    <parent link="camera_depth_frame"/>
    <child link="camera_right_ir_frame"/>
  </joint>
  <link name="camera_right_ir_frame"/>
  <joint name="camera_right_ir_optical_joint" type="fixed">
    <origin rpy="-1.57079632679 0 -1.57079632679" xyz="0 0 0"/>
    <parent link="camera_right_ir_frame"/>
    <child link="camera_right_ir_optical_frame"/>
  </joint>
  <link name="camera_right_ir_optical_frame"/>
  <!-- camera color joints and links -->
  <joint name="camera_color_joint" type="fixed">
    <origin rpy="0 0 0" xyz="0 0.015 0"/>
    <parent link="camera_depth_frame"/>
    <child link="camera_color_frame"/>
  </joint>
  <link name="camera_color_frame"/>
  <joint name="camera_color_optical_joint" type="fixed">
    <origin rpy="-1.57079632679 0 -1.57079632679" xyz="0 0 0"/>
    <parent link="camera_color_frame"/>
    <child link="camera_color_optical_frame"/>
  </joint>
  <link name="camera_color_optical_frame"/>
  <joint name="left_susp_joint" type="fixed">
    <parent link="base_link"/>
    <child link="left_susp_link"/>
    <origin xyz="0 0.19055 -0.39"/>
  </joint>
  <link name="left_susp_link">
    <visual>
      <geometry>
        <box size="0.0889 0.0889 0.05715"/>
      </geometry>
      <origin rpy="0 0 0" xyz="0 0 -0.028575"/>
      <material name="silver"/>
    </visual>
    <collision>
      <geometry>
        <box size="0.0889 0.0889 0.05715"/>
      </geometry>
      <origin rpy="0 0 0" xyz="0 0 -0.028575"/>
    </collision>
    <inertial>
      <mass value="1.5"/>
      <inertia ixx="0.00139616656244" ixy="0.0" ixz="0.0" iyy="0.00197580249992" iyz="0.0" izz="0.00139616656244"/>
    </inertial>
  </link>
  <joint name="right_susp_joint" type="fixed">
    <parent link="base_link"/>
    <child link="right_susp_link"/>
    <origin xyz="0 -0.19055 -0.39"/>
  </joint>
  <link name="right_susp_link">
    <visual>
      <geometry>
        <box size="0.0889 0.0889 0.05715"/>
      </geometry>
      <origin rpy="0 0 0" xyz="0 0 -0.028575"/>
      <material name="silver"/>
    </visual>
    <collision>
      <geometry>
        <box size="0.0889 0.0889 0.05715"/>
      </geometry>
      <origin rpy="0 0 0" xyz="0 0 -0.028575"/>
    </collision>
    <inertial>
      <mass value="1.5"/>
      <inertia ixx="0.00139616656244" ixy="0.0" ixz="0.0" iyy="0.00197580249992" iyz="0.0" izz="0.00139616656244"/>
    </inertial>
  </link>
  <joint name="left_motor_joint" type="fixed">
    <parent link="left_susp_link"/>
    <child link="left_motor_link"/>
    <origin xyz="0 0.005 -0.05715"/>
  </joint>
  <link name="left_motor_link">
    <visual>
      <geometry>
        <cylinder length="0.0989" radius="0.01905"/>
      </geometry>
      <origin rpy="1.57079632679 0 0" xyz="0 0 -0.01905"/>
      <material name="iron"/>
    </visual>
    <collision>
      <geometry>
        <cylinder length="0.0989" radius="0.01905"/>
      </geometry>
      <origin rpy="1.57079632679 0 0" xyz="0 0 -0.01905"/>
    </collision>
    <inertial>
      <mass value="1.0"/>
      <inertia ixx="0.000905826458297" ixy="0.0" ixz="0.0" iyy="0.000905826458297" iyz="0.0" izz="3.02418749988e-05"/>
    </inertial>
  </link>
  <joint name="right_motor_joint" type="fixed">
    <parent link="right_susp_link"/>
    <child link="right_motor_link"/>
    <origin xyz="0 -0.005 -0.05715"/>
  </joint>
  <link name="right_motor_link">
    <visual>
      <geometry>
        <cylinder length="0.0989" radius="0.01905"/>
      </geometry>
      <origin rpy="-1.57079632679 0 0" xyz="0 0 -0.01905"/>
      <material name="iron"/>
    </visual>
    <collision>
      <geometry>
        <cylinder length="0.0989" radius="0.01905"/>
      </geometry>
      <origin rpy="-1.57079632679 0 0" xyz="0 0 -0.01905"/>
    </collision>
    <inertial>
      <mass value="1.0"/>
      <inertia ixx="0.000905826458297" ixy="0.0" ixz="0.0" iyy="0.000905826458297" iyz="0.0" izz="3.02418749988e-05"/>
    </inertial>
  </link>
  <joint name="left_wheel_joint" type="continuous">
    <axis xyz="0 1 0"/>
    <parent link="left_motor_link"/>
    <child link="left_wheel_link"/>
    <origin rpy="0 0 0" xyz="0 0.04945 -0.01905"/>
  </joint>
  <link name="left_wheel_link">
    <visual>
      <geometry>
        <cylinder length="0.0254" radius="0.0762"/>
      </geometry>
      <origin rpy="1.57079632679 0 0" xyz="0 0.0127 0"/>
      <material name="black"/>
    </visual>
    <collision>
      <geometry>
        <cylinder length="0.0254" radius="0.0762"/>
      </geometry>
      <origin rpy="1.57079632679 0 0" xyz="0 0.0127 0"/>
    </collision>
    <inertial>
      <mass value="0.3"/>
      <inertia ixx="0.000451611999982" ixy="0.0" ixz="0.0" iyy="0.000451611999982" iyz="0.0" izz="0.000145160999994"/>
    </inertial>
  </link>
  <joint name="right_wheel_joint" type="continuous">
    <axis xyz="0 1 0"/>
    <parent link="right_motor_link"/>
    <child link="right_wheel_link"/>
    <origin rpy="0 0 0" xyz="0 -0.04945 -0.01905"/>
  </joint>
  <link name="right_wheel_link">
    <visual>
      <geometry>
        <cylinder length="0.0254" radius="0.0762"/>
      </geometry>
      <origin rpy="-1.57079632679 0 0" xyz="0 -0.0127 0"/>
      <material name="black"/>
    </visual>
    <collision>
      <geometry>
        <cylinder length="0.0254" radius="0.0762"/>
      </geometry>
      <origin rpy="-1.57079632679 0 0" xyz="0 -0.0127 0"/>
    </collision>
    <inertial>
      <mass value="0.3"/>
      <inertia ixx="0.000451611999982" ixy="0.0" ixz="0.0" iyy="0.000451611999982" iyz="0.0" izz="0.000145160999994"/>
    </inertial>
  </link>
  <!-- front right -->
  <joint name="caster_sup_front_right_joint" type="fixed">
    <parent link="base_link"/>
    <child link="caster_sup_front_right_link"/>
    <origin rpy="0 0 0" xyz="0.355 -0.21 -0.39"/>
  </joint>
  <link name="caster_sup_front_right_link">
    <visual>
      <geometry>
        <box size="0.05 0.05 0.0635"/>
      </geometry>
      <origin rpy="0 0 0" xyz="0 0 -0.03175"/>
      <material name="silver"/>
    </visual>
    <collision>
      <geometry>
        <box size="0.05 0.05 0.0635"/>
      </geometry>
      <origin rpy="0 0 0" xyz="0 0 -0.03175"/>
    </collision>
    <inertial>
      <mass value="1.0"/>
      <inertia ixx="0.003" ixy="0.0" ixz="0.0" iyy="0.003" iyz="0.0" izz="0.003"/>
    </inertial>
  </link>
  <joint name="caster_wheel_front_right_joint" type="fixed">
    <parent link="caster_sup_front_right_link"/>
    <child link="caster_wheel_front_right_link"/>
    <origin rpy="0 0 0" xyz="-0.025 0 -0.10795"/>
  </joint>
  <link name="caster_wheel_front_right_link">
    <visual>
      <geometry>
        <cylinder length="0.0254" radius="0.04445"/>
      </geometry>
      <origin rpy="-1.57079632679 0 0" xyz="0 0 0"/>
      <material name="black"/>
    </visual>
    <collision>
      <geometry>
        <cylinder length="0.0254" radius="0.04445"/>
      </geometry>
      <origin rpy="-1.57079632679 0 0" xyz="0 0 0"/>
    </collision>
    <inertial>
      <mass value="0.2"/>
      <inertia ixx="0.000109542791662" ixy="0.0" ixz="0.0" iyy="0.000109542791662" iyz="0.0" izz="3.29300416653e-05"/>
    </inertial>
  </link>
  <!-- front left -->
  <joint name="caster_sup_front_left_joint" type="fixed">
    <parent link="base_link"/>
    <child link="caster_sup_front_left_link"/>
    <origin rpy="0 0 0" xyz="0.355 0.21 -0.39"/>
  </joint>
  <link name="caster_sup_front_left_link">
    <visual>
      <geometry>
        <box size="0.05 0.05 0.0635"/>
      </geometry>
      <origin rpy="0 0 0" xyz="0 0 -0.03175"/>
      <material name="silver"/>
    </visual>
    <collision>
      <geometry>
        <box size="0.05 0.05 0.0635"/>
      </geometry>
      <origin rpy="0 0 0" xyz="0 0 -0.03175"/>
    </collision>
    <inertial>
      <mass value="1.0"/>
      <inertia ixx="0.003" ixy="0.0" ixz="0.0" iyy="0.003" iyz="0.0" izz="0.003"/>
    </inertial>
  </link>
  <joint name="caster_wheel_front_left_joint" type="fixed">
    <parent link="caster_sup_front_left_link"/>
    <child link="caster_wheel_front_left_link"/>
    <origin rpy="0 0 0" xyz="-0.025 0 -0.10795"/>
  </joint>
  <link name="caster_wheel_front_left_link">
    <visual>
      <geometry>
        <cylinder length="0.0254" radius="0.04445"/>
      </geometry>
      <origin rpy="1.57079632679 0 0" xyz="0 0 0"/>
      <material name="black"/>
    </visual>
    <collision>
      <geometry>
        <cylinder length="0.0254" radius="0.04445"/>
      </geometry>
      <origin rpy="1.57079632679 0 0" xyz="0 0 0"/>
    </collision>
    <inertial>
      <mass value="0.2"/>
      <inertia ixx="0.000109542791662" ixy="0.0" ixz="0.0" iyy="0.000109542791662" iyz="0.0" izz="3.29300416653e-05"/>
    </inertial>
  </link>
  <!-- back left -->
  <joint name="caster_sup_back_left_joint" type="fixed">
    <parent link="base_link"/>
    <child link="caster_sup_back_left_link"/>
    <origin rpy="0 0 0" xyz="-0.355 0.21 -0.39"/>
  </joint>
  <link name="caster_sup_back_left_link">
    <visual>
      <geometry>
        <box size="0.05 0.05 0.0635"/>
      </geometry>
      <origin rpy="0 0 0" xyz="0 0 -0.03175"/>
      <material name="silver"/>
    </visual>
    <collision>
      <geometry>
        <box size="0.05 0.05 0.0635"/>
      </geometry>
      <origin rpy="0 0 0" xyz="0 0 -0.03175"/>
    </collision>
    <inertial>
      <mass value="1.0"/>
      <inertia ixx="0.003" ixy="0.0" ixz="0.0" iyy="0.003" iyz="0.0" izz="0.003"/>
    </inertial>
  </link>
  <joint name="caster_wheel_back_left_joint" type="fixed">
    <parent link="caster_sup_back_left_link"/>
    <child link="caster_wheel_back_left_link"/>
    <origin rpy="0 0 0" xyz="-0.025 0 -0.10795"/>
  </joint>
  <link name="caster_wheel_back_left_link">
    <visual>
      <geometry>
        <cylinder length="0.0254" radius="0.04445"/>
      </geometry>
      <origin rpy="1.57079632679 0 0" xyz="0 0 0"/>
      <material name="black"/>
    </visual>
    <collision>
      <geometry>
        <cylinder length="0.0254" radius="0.04445"/>
      </geometry>
      <origin rpy="1.57079632679 0 0" xyz="0 0 0"/>
    </collision>
    <inertial>
      <mass value="0.2"/>
      <inertia ixx="0.000109542791662" ixy="0.0" ixz="0.0" iyy="0.000109542791662" iyz="0.0" izz="3.29300416653e-05"/>
    </inertial>
  </link>
  <!-- back right -->
  <joint name="caster_sup_back_right_joint" type="fixed">
    <parent link="base_link"/>
    <child link="caster_sup_back_right_link"/>
    <origin rpy="0 0 0" xyz="-0.355 -0.21 -0.39"/>
  </joint>
  <link name="caster_sup_back_right_link">
    <visual>
      <geometry>
        <box size="0.05 0.05 0.0635"/>
      </geometry>
      <origin rpy="0 0 0" xyz="0 0 -0.03175"/>
      <material name="silver"/>
    </visual>
    <collision>
      <geometry>
        <box size="0.05 0.05 0.0635"/>
      </geometry>
      <origin rpy="0 0 0" xyz="0 0 -0.03175"/>
    </collision>
    <inertial>
      <mass value="1.0"/>
      <inertia ixx="0.003" ixy="0.0" ixz="0.0" iyy="0.003" iyz="0.0" izz="0.003"/>
    </inertial>
  </link>
  <joint name="caster_wheel_back_right_joint" type="fixed">
    <parent link="caster_sup_back_right_link"/>
    <child link="caster_wheel_back_right_link"/>
    <origin rpy="0 0 0" xyz="-0.025 0 -0.10795"/>
  </joint>
  <link name="caster_wheel_back_right_link">
    <visual>
      <geometry>
        <cylinder length="0.0254" radius="0.04445"/>
      </geometry>
      <origin rpy="-1.57079632679 0 0" xyz="0 0 0"/>
      <material name="black"/>
    </visual>
    <collision>
      <geometry>
        <cylinder length="0.0254" radius="0.04445"/>
      </geometry>
      <origin rpy="-1.57079632679 0 0" xyz="0 0 0"/>
    </collision>
    <inertial>
      <mass value="0.2"/>
      <inertia ixx="0.000109542791662" ixy="0.0" ixz="0.0" iyy="0.000109542791662" iyz="0.0" izz="3.29300416653e-05"/>
    </inertial>
  </link>
</robot>
